Workbook

Sheet hạng mục CT
A2: Công ty CPXD&TM Gia Khánh | C2: Cộng hoà xã hội chủ nghĩa Việt Nam
A3: Tam Hiệp - Phúc Thọ - Hà Nội | C3: Độc lập - Tự do - Hạnh phúc
B6: NHÀ MÁY CÔNG NGHỆ RED BOARD VIỆT NAM
A9: Chuyển máy đến: | C9: Tổ trưởng máy : | D9: CHU THỜI QUYẾT
A10: Ngày chuyển máy | C10: Phụ trách ĐỖ VĂN ĐÔNG
A11: STT | B11: Hạng mục công việc | C11: ĐVT(M) | D11: Khối lượng | E11: Đơn giá | F11: Thành tiền | G11: Ghi chú
A12: I | B12: ÉP ĐẠI TRÀ
A13: 1 | B13: D350 | C13: md | D13: ='ÉP D350'!$V$24 | E13: 9000 | F13: =D13*E13
A14: 2 | B14: D300 | C14: md | D14: ='ÉP D300'!$V$62 | E14: 7500 | F14: =D14*E14
A15: II | B15: THÍ NGHIỆM
A16: 1 | B16: D350 | C16: điểm | D16: 2 | E16: 1200000 | F16: =D16*E16
A17: 2 | B17: D300 | C17: điểm | D17: 12 | E17: 1000000 | F17: =D17*E17
A18: III | B18: CẮT CỌC
A19: 1 | B19: D350 | C19: điểm | D19: ='ÉP D350'!$W$23 | E19: 40000 | F19: =D19*E19
A20: 2 | B20: D300 | C20: điểm | D20: ='ÉP D300'!$W$61 | E20: 30000 | F20: =D20*E20
A21: IV | B21: NÉN TĨNH
A22: 1 | B22: D350 | C22: điểm | E22: 1000000 | F22: =D22*E22
A23: 2 | B23: D300 | C23: điểm | D23: 7 | E23: 800000 | F23: =D23*E23
A24: V | B24: HẠ CỌC
A25: 1 | B25: PHỤ KATO HẠ D350 VÀ CỌC D300 | C25: md | D25: ='nhập cọc D300'!O17+'nhập cọc D350'!O12 | E25: 500 | F25: =D25*E25
A26: 2 | B26: ROBOT HẠ D350 | C26: md | E26: 1800 | F26: =D26*E26
A27: 3 | B27: ROBOT HẠ D300 | C27: md | E27: 1500 | F27: =D27*E27
A28: VI | B28: CÔNG NHẬT | C28: công nhật sửa chữa | D28: ='công nhật'!$F$14 | E28: 300000 | F28: =D28*E28
A29: VII | B29: VẬN HÀNH MÁY PHÁT | C29: =D13+D14 | D29: 300 | F29: =C29*D29
B30: trách nhiệm tổ trưởng + lái máy {8% x {1+2+3}} | C30: 0.08 | D30: =F14+F13 | F30: =C30*D30
A31: VIII | B31: Tháo + lắp máy | C31: lượt | D31: 2 | E31: 1500000 | F31: =D31*E31 | G31: bình xuyên- hưng yên
A32: TỔNG TIỀN | F32: =SUM(F13:F31)

Sheet ÉP D350
A1: BẢNG THỐNG KÊ KHỐI LƯỢNG CỌC
A2: CÔNG TRÌNH: NHÀ MÁY CÔNG NGHỆ RED BOARD VIỆT NAM
A3: NHÀ THẦU THI CÔNG: CÔNG TY TNHH XÂY DỰNG & XỬ LÝ NỀN MÓNG VIỆT HÙNG
A5: STT | B5: Ngày, tháng | C5: Máy ép | D5: Tên cọc | E5: Vị trí | F5: Loại cọc | G5: Tổ hợp cọc | L5: Chiều dài cọc | M5: Chiều dài cọc ép thực tế | N5: cắt cọc | O5: Ép âm, dương | P5: Lực ép | Q5: Ghi chú Remark
B6: Date | C6: Machine | D6: Pile name | E6: Location | F6: Pile type
G7: 1st | H7: 2nd | I7: 3rd | J7: 4th | K7: 5th
A8: 1 | B8: 46047 | C8: JVY420 | D8: TNBS-01 | E8: NHÀ XƯỞNG | F8: D350 | G8: 13 | H8: 13 | L8: =SUM(G8:K8) | M8: 21.8 | N8: =IF(L8-M8>0.1,1,0) | O8: =L8-M8 | P8: 182
A9: 2 | C9: JVY420 | D9: TNBS-02 | E9: NHÀ XƯỞNG | F9: D350 | G9: 13 | H9: 13 | L9: =SUM(G9:K9) | M9: 23.5 | N9: =IF(L9-M9>0.1,1,0) | O9: =L9-M9 | P9: 182
A10: TỔNG | L10: =SUM(L8:L9) | M10: =SUM(M8:M9) | N10: =SUM(N8:N9) | O10: =SUM(O8:O9) | P10: =SUM(P8:P9)
A14: CÔNG TY TNHH NISHIMATSU VIỆT NAM
R23: =SUM(#REF!) | S23: =SUM(#REF!) | T23: =SUM(#REF!) | V23: =SUM(#REF!) | W23: =SUM(N8:N9)
V24: =SUM(#REF!)
R26: 12 | S26: 13
R27: =SUMIF(#REF!,#REF!,#REF!) | S27: =$S$23
R28: =+R27 | S28: =S27
V30: CÔNG TY TNHH XÂY DỰNG & XỬ LÝ NỀN MÓNG VIỆT HÙNG

Sheet ÉP D300
A1: BẢNG THỐNG KÊ KHỐI LƯỢNG CỌC
A2: CÔNG TRÌNH: NHÀ MÁY CÔNG NGHỆ RED BOARD VIỆT NAM
A3: NHÀ THẦU THI CÔNG: CÔNG TY TNHH XÂY DỰNG & XỬ LÝ NỀN MÓNG VIỆT HÙNG
A5: STT | B5: Ngày, tháng | C5: Máy ép | D5: Tên cọc | E5: Vị trí | F5: Loại cọc | G5: Tổ hợp cọc / Pile detail length (m) | L5: Tổng hợp / Total (m) | U5: Chiều dài cọc / Total of pile detail length (m) | V5: Chiều dài cọc ép thực tế / Length of pile under ground (m) | W5: cắt cọc | X5: Ép âm, dương / Length of pile pressing positive (m) | Y5: Lực ép / Pressing force (Ton) | Z5: Ghi chú Remark
B6: Date | C6: Machine | D6: Pile name | E6: Location | F6: Pile type
G7: 1st | H7: 2nd | I7: 3rd | J7: 4th | K7: 5th | L7: 6 | M7: 7 | N7: 8 | O7: 9 | P7: 10 | Q7: 11 | R7: 12 | S7: 13 | T7: 14
A8: 1 | B8: 46047 | C8: JVY420 | D8: TNB-03 | E8: NHÀ XƯỞNG | F8: D300 | G8: 10 | H8: 10 | I8: 10 | L8: =IF(G8=$L$7,1,0)+IF(H8=$L$7,1,0)+IF(I8=$L$7,1,0)+IF(J8=$L$7,1,0)+IF(K8=$L$7,1,0) | M8: =IF(G8=$M$7,1,0)+IF(H8=$M$7,1,0)+IF(I8=$M$7,1,0)+IF(J8=$M$7,1,0)+IF(K8=$M$7,1,0) | N8: =IF(G8=$N$7,1,0)+IF(H8=$N$7,1,0)+IF(I8=$N$7,1,0)+IF(J8=$N$7,1,0)+IF(K8=$N$7,1,0) | O8: =IF(G8=$O$7,1,0)+IF(H8=$O$7,1,0)+IF(I8=$O$7,1,0)+IF(J8=$O$7,1,0)+IF(K8=$O$7,1,0) | P8: =IF(G8=$P$7,1,0)+IF(H8=$P$7,1,0)+IF(I8=$P$7,1,0)+IF(J8=$P$7,1,0)+IF(K8=$P$7,1,0) | Q8: =IF(G8=$Q$7,1,0)+IF(H8=$Q$7,1,0)+IF(I8=$Q$7,1,0)+IF(J8=$Q$7,1,0)+IF(K8=$Q$7,1,0) | R8: =IF(G8=$R$7,1,0)+IF(H8=$R$7,1,0)+IF(I8=$R$7,1,0)+IF(J8=$R$7,1,0)+IF(K8=$R$7,1,0) | S8: =IF(G8=$S$7,1,0)+IF(H8=$S$7,1,0)+IF(I8=$S$7,1,0)+IF(J8=$S$7,1,0)+IF(K8=$S$7,1,0) | T8: =IF(G8=$T$7,1,0)+IF(H8=$T$7,1,0)+IF(I8=$T$7,1,0)+IF(J8=$T$7,1,0)+IF(K8=$T$7,1,0) | U8: =SUM(G8:K8) | V8: 23.8 | W8: =IF(U8-V8>0.1,1,0) | X8: =U8-V8 | Y8: 150 | Z8: THÍ NGHIỆM
A9: 2 | C9: JVY420 | D9: TNB-01 | E9: NHÀ XƯỞNG | F9: D300 | G9: 13 | H9: 13 | L9: =IF(G9=$L$7,1,0)+IF(H9=$L$7,1,0)+IF(I9=$L$7,1,0)+IF(J9=$L$7,1,0)+IF(K9=$L$7,1,0) | M9: =IF(G9=$M$7,1,0)+IF(H9=$M$7,1,0)+IF(I9=$M$7,1,0)+IF(J9=$M$7,1,0)+IF(K9=$M$7,1,0) | N9: =IF(G9=$N$7,1,0)+IF(H9=$N$7,1,0)+IF(I9=$N$7,1,0)+IF(J9=$N$7,1,0)+IF(K9=$N$7,1,0) | O9: =IF(G9=$O$7,1,0)+IF(H9=$O$7,1,0)+IF(I9=$O$7,1,0)+IF(J9=$O$7,1,0)+IF(K9=$O$7,1,0) | P9: =IF(G9=$P$7,1,0)+IF(H9=$P$7,1,0)+IF(I9=$P$7,1,0)+IF(J9=$P$7,1,0)+IF(K9=$P$7,1,0) | Q9: =IF(G9=$Q$7,1,0)+IF(H9=$Q$7,1,0)+IF(I9=$Q$7,1,0)+IF(J9=$Q$7,1,0)+IF(K9=$Q$7,1,0) | R9: =IF(G9=$R$7,1,0)+IF(H9=$R$7,1,0)+IF(I9=$R$7,1,0)+IF(J9=$R$7,1,0)+IF(K9=$R$7,1,0) | S9: =IF(G9=$S$7,1,0)+IF(H9=$S$7,1,0)+IF(I9=$S$7,1,0)+IF(J9=$S$7,1,0)+IF(K9=$S$7,1,0) | T9: =IF(G9=$T$7,1,0)+IF(H9=$T$7,1,0)+IF(I9=$T$7,1,0)+IF(J9=$T$7,1,0)+IF(K9=$T$7,1,0) | U9: =SUM(G9:K9) | V9: 25 | W9: =IF(U9-V9>0.1,1,0) | X9: =U9-V9 | Y9: 150 | Z9: THÍ NGHIỆM
A10: 3 | B10: 46048 | C10: JVY420 | D10: TNB-02 | E10: NHÀ XƯỞNG | F10: D300 | G10: 10 | H10: 10 | I10: 10 | L10: =IF(G10=$L$7,1,0)+IF(H10=$L$7,1,0)+IF(I10=$L$7,1,0)+IF(J10=$L$7,1,0)+IF(K10=$L$7,1,0) | M10: =IF(G10=$M$7,1,0)+IF(H10=$M$7,1,0)+IF(I10=$M$7,1,0)+IF(J10=$M$7,1,0)+IF(K10=$M$7,1,0) | N10: =IF(G10=$N$7,1,0)+IF(H10=$N$7,1,0)+IF(I10=$N$7,1,0)+IF(J10=$N$7,1,0)+IF(K10=$N$7,1,0) | O10: =IF(G10=$O$7,1,0)+IF(H10=$O$7,1,0)+IF(I10=$O$7,1,0)+IF(J10=$O$7,1,0)+IF(K10=$O$7,1,0) | P10: =IF(G10=$P$7,1,0)+IF(H10=$P$7,1,0)+IF(I10=$P$7,1,0)+IF(J10=$P$7,1,0)+IF(K10=$P$7,1,0) | Q10: =IF(G10=$Q$7,1,0)+IF(H10=$Q$7,1,0)+IF(I10=$Q$7,1,0)+IF(J10=$Q$7,1,0)+IF(K10=$Q$7,1,0) | R10: =IF(G10=$R$7,1,0)+IF(H10=$R$7,1,0)+IF(I10=$R$7,1,0)+IF(J10=$R$7,1,0)+IF(K10=$R$7,1,0) | S10: =IF(G10=$S$7,1,0)+IF(H10=$S$7,1,0)+IF(I10=$S$7,1,0)+IF(J10=$S$7,1,0)+IF(K10=$S$7,1,0) | T10: =IF(G10=$T$7,1,0)+IF(H10=$T$7,1,0)+IF(I10=$T$7,1,0)+IF(J10=$T$7,1,0)+IF(K10=$T$7,1,0) | U10: =SUM(G10:K10) | V10: 23.5 | W10: =IF(U10-V10>0.1,1,0) | X10: =U10-V10 | Y10: 150 | Z10: THÍ NGHIỆM
A11: 4 | C11: JVY420 | D11: TNB-04 | E11: NHÀ XƯỞNG | F11: D300 | G11: 13 | H11: 13 | L11: =IF(G11=$L$7,1,0)+IF(H11=$L$7,1,0)+IF(I11=$L$7,1,0)+IF(J11=$L$7,1,0)+IF(K11=$L$7,1,0) | M11: =IF(G11=$M$7,1,0)+IF(H11=$M$7,1,0)+IF(I11=$M$7,1,0)+IF(J11=$M$7,1,0)+IF(K11=$M$7,1,0) | N11: =IF(G11=$N$7,1,0)+IF(H11=$N$7,1,0)+IF(I11=$N$7,1,0)+IF(J11=$N$7,1,0)+IF(K11=$N$7,1,0) | O11: =IF(G11=$O$7,1,0)+IF(H11=$O$7,1,0)+IF(I11=$O$7,1,0)+IF(J11=$O$7,1,0)+IF(K11=$O$7,1,0) | P11: =IF(G11=$P$7,1,0)+IF(H11=$P$7,1,0)+IF(I11=$P$7,1,0)+IF(J11=$P$7,1,0)+IF(K11=$P$7,1,0) | Q11: =IF(G11=$Q$7,1,0)+IF(H11=$Q$7,1,0)+IF(I11=$Q$7,1,0)+IF(J11=$Q$7,1,0)+IF(K11=$Q$7,1,0) | R11: =IF(G11=$R$7,1,0)+IF(H11=$R$7,1,0)+IF(I11=$R$7,1,0)+IF(J11=$R$7,1,0)+IF(K11=$R$7,1,0) | S11: =IF(G11=$S$7,1,0)+IF(H11=$S$7,1,0)+IF(I11=$S$7,1,0)+IF(J11=$S$7,1,0)+IF(K11=$S$7,1,0) | T11: =IF(G11=$T$7,1,0)+IF(H11=$T$7,1,0)+IF(I11=$T$7,1,0)+IF(J11=$T$7,1,0)+IF(K11=$T$7,1,0) | U11: =SUM(G11:K11) | V11: 22.2 | W11: =IF(U11-V11>0.1,1,0) | X11: =U11-V11 | Y11: 150 | Z11: THÍ NGHIỆM
A12: 5 | B12: 46049 | C12: JVY420 | D12: TNB-05 | E12: NHÀ XƯỞNG | F12: D300 | G12: 13 | H12: 13 | L12: =IF(G12=$L$7,1,0)+IF(H12=$L$7,1,0)+IF(I12=$L$7,1,0)+IF(J12=$L$7,1,0)+IF(K12=$L$7,1,0) | M12: =IF(G12=$M$7,1,0)+IF(H12=$M$7,1,0)+IF(I12=$M$7,1,0)+IF(J12=$M$7,1,0)+IF(K12=$M$7,1,0) | N12: =IF(G12=$N$7,1,0)+IF(H12=$N$7,1,0)+IF(I12=$N$7,1,0)+IF(J12=$N$7,1,0)+IF(K12=$N$7,1,0) | O12: =IF(G12=$O$7,1,0)+IF(H12=$O$7,1,0)+IF(I12=$O$7,1,0)+IF(J12=$O$7,1,0)+IF(K12=$O$7,1,0) | P12: =IF(G12=$P$7,1,0)+IF(H12=$P$7,1,0)+IF(I12=$P$7,1,0)+IF(J12=$P$7,1,0)+IF(K12=$P$7,1,0) | Q12: =IF(G12=$Q$7,1,0)+IF(H12=$Q$7,1,0)+IF(I12=$Q$7,1,0)+IF(J12=$Q$7,1,0)+IF(K12=$Q$7,1,0) | R12: =IF(G12=$R$7,1,0)+IF(H12=$R$7,1,0)+IF(I12=$R$7,1,0)+IF(J12=$R$7,1,0)+IF(K12=$R$7,1,0) | S12: =IF(G12=$S$7,1,0)+IF(H12=$S$7,1,0)+IF(I12=$S$7,1,0)+IF(J12=$S$7,1,0)+IF(K12=$S$7,1,0) | T12: =IF(G12=$T$7,1,0)+IF(H12=$T$7,1,0)+IF(I12=$T$7,1,0)+IF(J12=$T$7,1,0)+IF(K12=$T$7,1,0) | U12: =SUM(G12:K12) | V12: 23.3 | W12: =IF(U12-V12>0.1,1,0) | X12: =U12-V12 | Y12: 150 | Z12: THÍ NGHIỆM
A13: 6 | C13: JVY420 | D13: TNB-06 | E13: NHÀ XƯỞNG | F13: D300 | G13: 13 | H13: 13 | L13: =IF(G13=$L$7,1,0)+IF(H13=$L$7,1,0)+IF(I13=$L$7,1,0)+IF(J13=$L$7,1,0)+IF(K13=$L$7,1,0) | M13: =IF(G13=$M$7,1,0)+IF(H13=$M$7,1,0)+IF(I13=$M$7,1,0)+IF(J13=$M$7,1,0)+IF(K13=$M$7,1,0) | N13: =IF(G13=$N$7,1,0)+IF(H13=$N$7,1,0)+IF(I13=$N$7,1,0)+IF(J13=$N$7,1,0)+IF(K13=$N$7,1,0) | O13: =IF(G13=$O$7,1,0)+IF(H13=$O$7,1,0)+IF(I13=$O$7,1,0)+IF(J13=$O$7,1,0)+IF(K13=$O$7,1,0) | P13: =IF(G13=$P$7,1,0)+IF(H13=$P$7,1,0)+IF(I13=$P$7,1,0)+IF(J13=$P$7,1,0)+IF(K13=$P$7,1,0) | Q13: =IF(G13=$Q$7,1,0)+IF(H13=$Q$7,1,0)+IF(I13=$Q$7,1,0)+IF(J13=$Q$7,1,0)+IF(K13=$Q$7,1,0) | R13: =IF(G13=$R$7,1,0)+IF(H13=$R$7,1,0)+IF(I13=$R$7,1,0)+IF(J13=$R$7,1,0)+IF(K13=$R$7,1,0) | S13: =IF(G13=$S$7,1,0)+IF(H13=$S$7,1,0)+IF(I13=$S$7,1,0)+IF(J13=$S$7,1,0)+IF(K13=$S$7,1,0) | T13: =IF(G13=$T$7,1,0)+IF(H13=$T$7,1,0)+IF(I13=$T$7,1,0)+IF(J13=$T$7,1,0)+IF(K13=$T$7,1,0) | U13: =SUM(G13:K13) | V13: 23.8 | W13: =IF(U13-V13>0.1,1,0) | X13: =U13-V13 | Y13: 150 | Z13: THÍ NGHIỆM
A14: 7 | C14: JVY420 | D14: TNB-07 | E14: NHÀ XƯỞNG | F14: D300 | G14: 13 | H14: 13 | L14: =IF(G14=$L$7,1,0)+IF(H14=$L$7,1,0)+IF(I14=$L$7,1,0)+IF(J14=$L$7,1,0)+IF(K14=$L$7,1,0) | M14: =IF(G14=$M$7,1,0)+IF(H14=$M$7,1,0)+IF(I14=$M$7,1,0)+IF(J14=$M$7,1,0)+IF(K14=$M$7,1,0) | N14: =IF(G14=$N$7,1,0)+IF(H14=$N$7,1,0)+IF(I14=$N$7,1,0)+IF(J14=$N$7,1,0)+IF(K14=$N$7,1,0) | O14: =IF(G14=$O$7,1,0)+IF(H14=$O$7,1,0)+IF(I14=$O$7,1,0)+IF(J14=$O$7,1,0)+IF(K14=$O$7,1,0) | P14: =IF(G14=$P$7,1,0)+IF(H14=$P$7,1,0)+IF(I14=$P$7,1,0)+IF(J14=$P$7,1,0)+IF(K14=$P$7,1,0) | Q14: =IF(G14=$Q$7,1,0)+IF(H14=$Q$7,1,0)+IF(I14=$Q$7,1,0)+IF(J14=$Q$7,1,0)+IF(K14=$Q$7,1,0) | R14: =IF(G14=$R$7,1,0)+IF(H14=$R$7,1,0)+IF(I14=$R$7,1,0)+IF(J14=$R$7,1,0)+IF(K14=$R$7,1,0) | S14: =IF(G14=$S$7,1,0)+IF(H14=$S$7,1,0)+IF(I14=$S$7,1,0)+IF(J14=$S$7,1,0)+IF(K14=$S$7,1,0) | T14: =IF(G14=$T$7,1,0)+IF(H14=$T$7,1,0)+IF(I14=$T$7,1,0)+IF(J14=$T$7,1,0)+IF(K14=$T$7,1,0) | U14: =SUM(G14:K14) | V14: 17 | W14: =IF(U14-V14>0.1,1,0) | X14: =U14-V14 | Y14: 150 | Z14: THÍ NGHIỆM
A15: 8 | C15: JVY420 | D15: TNB-08 | E15: NHÀ XƯỞNG | F15: D300 | G15: 13 | H15: 13 | L15: =IF(G15=$L$7,1,0)+IF(H15=$L$7,1,0)+IF(I15=$L$7,1,0)+IF(J15=$L$7,1,0)+IF(K15=$L$7,1,0) | M15: =IF(G15=$M$7,1,0)+IF(H15=$M$7,1,0)+IF(I15=$M$7,1,0)+IF(J15=$M$7,1,0)+IF(K15=$M$7,1,0) | N15: =IF(G15=$N$7,1,0)+IF(H15=$N$7,1,0)+IF(I15=$N$7,1,0)+IF(J15=$N$7,1,0)+IF(K15=$N$7,1,0) | O15: =IF(G15=$O$7,1,0)+IF(H15=$O$7,1,0)+IF(I15=$O$7,1,0)+IF(J15=$O$7,1,0)+IF(K15=$O$7,1,0) | P15: =IF(G15=$P$7,1,0)+IF(H15=$P$7,1,0)+IF(I15=$P$7,1,0)+IF(J15=$P$7,1,0)+IF(K15=$P$7,1,0) | Q15: =IF(G15=$Q$7,1,0)+IF(H15=$Q$7,1,0)+IF(I15=$Q$7,1,0)+IF(J15=$Q$7,1,0)+IF(K15=$Q$7,1,0) | R15: =IF(G15=$R$7,1,0)+IF(H15=$R$7,1,0)+IF(I15=$R$7,1,0)+IF(J15=$R$7,1,0)+IF(K15=$R$7,1,0) | S15: =IF(G15=$S$7,1,0)+IF(H15=$S$7,1,0)+IF(I15=$S$7,1,0)+IF(J15=$S$7,1,0)+IF(K15=$S$7,1,0) | T15: =IF(G15=$T$7,1,0)+IF(H15=$T$7,1,0)+IF(I15=$T$7,1,0)+IF(J15=$T$7,1,0)+IF(K15=$T$7,1,0) | U15: =SUM(G15:K15) | V15: 24 | W15: =IF(U15-V15>0.1,1,0) | X15: =U15-V15 | Y15: 150 | Z15: THÍ NGHIỆM
A16: 9 | B16: 46050 | C16: JVY420 | D16: N01 | E16: NHÀ XƯỞNG | F16: D300 | G16: 13 | H16: 13 | L16: =IF(G16=$L$7,1,0)+IF(H16=$L$7,1,0)+IF(I16=$L$7,1,0)+IF(J16=$L$7,1,0)+IF(K16=$L$7,1,0) | M16: =IF(G16=$M$7,1,0)+IF(H16=$M$7,1,0)+IF(I16=$M$7,1,0)+IF(J16=$M$7,1,0)+IF(K16=$M$7,1,0) | N16: =IF(G16=$N$7,1,0)+IF(H16=$N$7,1,0)+IF(I16=$N$7,1,0)+IF(J16=$N$7,1,0)+IF(K16=$N$7,1,0) | O16: =IF(G16=$O$7,1,0)+IF(H16=$O$7,1,0)+IF(I16=$O$7,1,0)+IF(J16=$O$7,1,0)+IF(K16=$O$7,1,0) | P16: =IF(G16=$P$7,1,0)+IF(H16=$P$7,1,0)+IF(I16=$P$7,1,0)+IF(J16=$P$7,1,0)+IF(K16=$P$7,1,0) | Q16: =IF(G16=$Q$7,1,0)+IF(H16=$Q$7,1,0)+IF(I16=$Q$7,1,0)+IF(J16=$Q$7,1,0)+IF(K16=$Q$7,1,0) | R16: =IF(G16=$R$7,1,0)+IF(H16=$R$7,1,0)+IF(I16=$R$7,1,0)+IF(J16=$R$7,1,0)+IF(K16=$R$7,1,0) | S16: =IF(G16=$S$7,1,0)+IF(H16=$S$7,1,0)+IF(I16=$S$7,1,0)+IF(J16=$S$7,1,0)+IF(K16=$S$7,1,0) | T16: =IF(G16=$T$7,1,0)+IF(H16=$T$7,1,0)+IF(I16=$T$7,1,0)+IF(J16=$T$7,1,0)+IF(K16=$T$7,1,0) | U16: =SUM(G16:K16) | V16: 23.2 | W16: =IF(U16-V16>0.1,1,0) | X16: =U16-V16 | Y16: 150 | Z16: THÍ NGHIỆM
A17: 10 | C17: JVY420 | D17: N02 | E17: NHÀ XE | F17: D300 | G17: 13 | H17: 13 | L17: =IF(G17=$L$7,1,0)+IF(H17=$L$7,1,0)+IF(I17=$L$7,1,0)+IF(J17=$L$7,1,0)+IF(K17=$L$7,1,0) | M17: =IF(G17=$M$7,1,0)+IF(H17=$M$7,1,0)+IF(I17=$M$7,1,0)+IF(J17=$M$7,1,0)+IF(K17=$M$7,1,0) | N17: =IF(G17=$N$7,1,0)+IF(H17=$N$7,1,0)+IF(I17=$N$7,1,0)+IF(J17=$N$7,1,0)+IF(K17=$N$7,1,0) | O17: =IF(G17=$O$7,1,0)+IF(H17=$O$7,1,0)+IF(I17=$O$7,1,0)+IF(J17=$O$7,1,0)+IF(K17=$O$7,1,0) | P17: =IF(G17=$P$7,1,0)+IF(H17=$P$7,1,0)+IF(I17=$P$7,1,0)+IF(J17=$P$7,1,0)+IF(K17=$P$7,1,0) | Q17: =IF(G17=$Q$7,1,0)+IF(H17=$Q$7,1,0)+IF(I17=$Q$7,1,0)+IF(J17=$Q$7,1,0)+IF(K17=$Q$7,1,0) | R17: =IF(G17=$R$7,1,0)+IF(H17=$R$7,1,0)+IF(I17=$R$7,1,0)+IF(J17=$R$7,1,0)+IF(K17=$R$7,1,0) | S17: =IF(G17=$S$7,1,0)+IF(H17=$S$7,1,0)+IF(I17=$S$7,1,0)+IF(J17=$S$7,1,0)+IF(K17=$S$7,1,0) | T17: =IF(G17=$T$7,1,0)+IF(H17=$T$7,1,0)+IF(I17=$T$7,1,0)+IF(J17=$T$7,1,0)+IF(K17=$T$7,1,0) | U17: =SUM(G17:K17) | V17: 23.7 | W17: =IF(U17-V17>0.1,1,0) | X17: =U17-V17 | Y17: 150 | Z17: THÍ NGHIỆM
A18: 11 | B18: 46051 | C18: JVY420 | D18: N03 | E18: NHÀ XE | F18: D300 | G18: 13 | H18: 13 | L18: =IF(G18=$L$7,1,0)+IF(H18=$L$7,1,0)+IF(I18=$L$7,1,0)+IF(J18=$L$7,1,0)+IF(K18=$L$7,1,0) | M18: =IF(G18=$M$7,1,0)+IF(H18=$M$7,1,0)+IF(I18=$M$7,1,0)+IF(J18=$M$7,1,0)+IF(K18=$M$7,1,0) | N18: =IF(G18=$N$7,1,0)+IF(H18=$N$7,1,0)+IF(I18=$N$7,1,0)+IF(J18=$N$7,1,0)+IF(K18=$N$7,1,0) | O18: =IF(G18=$O$7,1,0)+IF(H18=$O$7,1,0)+IF(I18=$O$7,1,0)+IF(J18=$O$7,1,0)+IF(K18=$O$7,1,0) | P18: =IF(G18=$P$7,1,0)+IF(H18=$P$7,1,0)+IF(I18=$P$7,1,0)+IF(J18=$P$7,1,0)+IF(K18=$P$7,1,0) | Q18: =IF(G18=$Q$7,1,0)+IF(H18=$Q$7,1,0)+IF(I18=$Q$7,1,0)+IF(J18=$Q$7,1,0)+IF(K18=$Q$7,1,0) | R18: =IF(G18=$R$7,1,0)+IF(H18=$R$7,1,0)+IF(I18=$R$7,1,0)+IF(J18=$R$7,1,0)+IF(K18=$R$7,1,0) | S18: =IF(G18=$S$7,1,0)+IF(H18=$S$7,1,0)+IF(I18=$S$7,1,0)+IF(J18=$S$7,1,0)+IF(K18=$S$7,1,0) | T18: =IF(G18=$T$7,1,0)+IF(H18=$T$7,1,0)+IF(I18=$T$7,1,0)+IF(J18=$T$7,1,0)+IF(K18=$T$7,1,0) | U18: =SUM(G18:K18) | V18: 23.4 | W18: =IF(U18-V18>0.1,1,0) | X18: =U18-V18 | Y18: 150 | Z18: THÍ NGHIỆM
A19: 12 | C19: JVY420 | D19: N04 | E19: NHÀ XE | F19: D300 | G19: 10 | H19: 10 | I19: 10 | L19: =IF(G19=$L$7,1,0)+IF(H19=$L$7,1,0)+IF(I19=$L$7,1,0)+IF(J19=$L$7,1,0)+IF(K19=$L$7,1,0) | M19: =IF(G19=$M$7,1,0)+IF(H19=$M$7,1,0)+IF(I19=$M$7,1,0)+IF(J19=$M$7,1,0)+IF(K19=$M$7,1,0) | N19: =IF(G19=$N$7,1,0)+IF(H19=$N$7,1,0)+IF(I19=$N$7,1,0)+IF(J19=$N$7,1,0)+IF(K19=$N$7,1,0) | O19: =IF(G19=$O$7,1,0)+IF(H19=$O$7,1,0)+IF(I19=$O$7,1,0)+IF(J19=$O$7,1,0)+IF(K19=$O$7,1,0) | P19: =IF(G19=$P$7,1,0)+IF(H19=$P$7,1,0)+IF(I19=$P$7,1,0)+IF(J19=$P$7,1,0)+IF(K19=$P$7,1,0) | Q19: =IF(G19=$Q$7,1,0)+IF(H19=$Q$7,1,0)+IF(I19=$Q$7,1,0)+IF(J19=$Q$7,1,0)+IF(K19=$Q$7,1,0) | R19: =IF(G19=$R$7,1,0)+IF(H19=$R$7,1,0)+IF(I19=$R$7,1,0)+IF(J19=$R$7,1,0)+IF(K19=$R$7,1,0) | S19: =IF(G19=$S$7,1,0)+IF(H19=$S$7,1,0)+IF(I19=$S$7,1,0)+IF(J19=$S$7,1,0)+IF(K19=$S$7,1,0) | T19: =IF(G19=$T$7,1,0)+IF(H19=$T$7,1,0)+IF(I19=$T$7,1,0)+IF(J19=$T$7,1,0)+IF(K19=$T$7,1,0) | U19: =SUM(G19:K19) | V19: 24 | W19: =IF(U19-V19>0.1,1,0) | X19: =U19-V19 | Y19: 150 | Z19: THÍ NGHIỆM
A20: 1 | B20: 46081 | C20: JVY420 | D20: L9 | E20: NHÀ XƯỞNG | F20: D300 | G20: 12 | H20: 12 | L20: =IF(G20=$L$7,1,0)+IF(H20=$L$7,1,0)+IF(I20=$L$7,1,0)+IF(J20=$L$7,1,0)+IF(K20=$L$7,1,0) | M20: =IF(G20=$M$7,1,0)+IF(H20=$M$7,1,0)+IF(I20=$M$7,1,0)+IF(J20=$M$7,1,0)+IF(K20=$M$7,1,0) | N20: =IF(G20=$N$7,1,0)+IF(H20=$N$7,1,0)+IF(I20=$N$7,1,0)+IF(J20=$N$7,1,0)+IF(K20=$N$7,1,0) | O20: =IF(G20=$O$7,1,0)+IF(H20=$O$7,1,0)+IF(I20=$O$7,1,0)+IF(J20=$O$7,1,0)+IF(K20=$O$7,1,0) | P20: =IF(G20=$P$7,1,0)+IF(H20=$P$7,1,0)+IF(I20=$P$7,1,0)+IF(J20=$P$7,1,0)+IF(K20=$P$7,1,0) | Q20: =IF(G20=$Q$7,1,0)+IF(H20=$Q$7,1,0)+IF(I20=$Q$7,1,0)+IF(J20=$Q$7,1,0)+IF(K20=$Q$7,1,0) | R20: =IF(G20=$R$7,1,0)+IF(H20=$R$7,1,0)+IF(I20=$R$7,1,0)+IF(J20=$R$7,1,0)+IF(K20=$R$7,1,0) | S20: =IF(G20=$S$7,1,0)+IF(H20=$S$7,1,0)+IF(I20=$S$7,1,0)+IF(J20=$S$7,1,0)+IF(K20=$S$7,1,0) | T20: =IF(G20=$T$7,1,0)+IF(H20=$T$7,1,0)+IF(I20=$T$7,1,0)+IF(J20=$T$7,1,0)+IF(K20=$T$7,1,0) | U20: =SUM(G20:K20) | V20: 24 | W20: =IF(U20-V20>0.1,1,0) | X20: =U20-V20 | Y20: 140
A21: 2 | C21: JVY420 | D21: L13 | E21: NHÀ XƯỞNG | F21: D300 | G21: 12 | H21: 12 | L21: =IF(G21=$L$7,1,0)+IF(H21=$L$7,1,0)+IF(I21=$L$7,1,0)+IF(J21=$L$7,1,0)+IF(K21=$L$7,1,0) | M21: =IF(G21=$M$7,1,0)+IF(H21=$M$7,1,0)+IF(I21=$M$7,1,0)+IF(J21=$M$7,1,0)+IF(K21=$M$7,1,0) | N21: =IF(G21=$N$7,1,0)+IF(H21=$N$7,1,0)+IF(I21=$N$7,1,0)+IF(J21=$N$7,1,0)+IF(K21=$N$7,1,0) | O21: =IF(G21=$O$7,1,0)+IF(H21=$O$7,1,0)+IF(I21=$O$7,1,0)+IF(J21=$O$7,1,0)+IF(K21=$O$7,1,0) | P21: =IF(G21=$P$7,1,0)+IF(H21=$P$7,1,0)+IF(I21=$P$7,1,0)+IF(J21=$P$7,1,0)+IF(K21=$P$7,1,0) | Q21: =IF(G21=$Q$7,1,0)+IF(H21=$Q$7,1,0)+IF(I21=$Q$7,1,0)+IF(J21=$Q$7,1,0)+IF(K21=$Q$7,1,0) | R21: =IF(G21=$R$7,1,0)+IF(H21=$R$7,1,0)+IF(I21=$R$7,1,0)+IF(J21=$R$7,1,0)+IF(K21=$R$7,1,0) | S21: =IF(G21=$S$7,1,0)+IF(H21=$S$7,1,0)+IF(I21=$S$7,1,0)+IF(J21=$S$7,1,0)+IF(K21=$S$7,1,0) | T21: =IF(G21=$T$7,1,0)+IF(H21=$T$7,1,0)+IF(I21=$T$7,1,0)+IF(J21=$T$7,1,0)+IF(K21=$T$7,1,0) | U21: =SUM(G21:K21) | V21: 20 | W21: =IF(U21-V21>0.1,1,0) | X21: =U21-V21 | Y21: 90
A22: 3 | C22: JVY420 | D22: L13A | E22: NHÀ XƯỞNG | F22: D300 | G22: 12 | H22: 12 | L22: =IF(G22=$L$7,1,0)+IF(H22=$L$7,1,0)+IF(I22=$L$7,1,0)+IF(J22=$L$7,1,0)+IF(K22=$L$7,1,0) | M22: =IF(G22=$M$7,1,0)+IF(H22=$M$7,1,0)+IF(I22=$M$7,1,0)+IF(J22=$M$7,1,0)+IF(K22=$M$7,1,0) | N22: =IF(G22=$N$7,1,0)+IF(H22=$N$7,1,0)+IF(I22=$N$7,1,0)+IF(J22=$N$7,1,0)+IF(K22=$N$7,1,0) | O22: =IF(G22=$O$7,1,0)+IF(H22=$O$7,1,0)+IF(I22=$O$7,1,0)+IF(J22=$O$7,1,0)+IF(K22=$O$7,1,0) | P22: =IF(G22=$P$7,1,0)+IF(H22=$P$7,1,0)+IF(I22=$P$7,1,0)+IF(J22=$P$7,1,0)+IF(K22=$P$7,1,0) | Q22: =IF(G22=$Q$7,1,0)+IF(H22=$Q$7,1,0)+IF(I22=$Q$7,1,0)+IF(J22=$Q$7,1,0)+IF(K22=$Q$7,1,0) | R22: =IF(G22=$R$7,1,0)+IF(H22=$R$7,1,0)+IF(I22=$R$7,1,0)+IF(J22=$R$7,1,0)+IF(K22=$R$7,1,0) | S22: =IF(G22=$S$7,1,0)+IF(H22=$S$7,1,0)+IF(I22=$S$7,1,0)+IF(J22=$S$7,1,0)+IF(K22=$S$7,1,0) | T22: =IF(G22=$T$7,1,0)+IF(H22=$T$7,1,0)+IF(I22=$T$7,1,0)+IF(J22=$T$7,1,0)+IF(K22=$T$7,1,0) | U22: =SUM(G22:K22) | V22: 24 | W22: =IF(U22-V22>0.1,1,0) | X22: =U22-V22 | Y22: 140
A23: 4 | C23: JVY420 | D23: L17 | E23: NHÀ XƯỞNG | F23: D300 | G23: 12 | H23: 12 | L23: =IF(G23=$L$7,1,0)+IF(H23=$L$7,1,0)+IF(I23=$L$7,1,0)+IF(J23=$L$7,1,0)+IF(K23=$L$7,1,0) | M23: =IF(G23=$M$7,1,0)+IF(H23=$M$7,1,0)+IF(I23=$M$7,1,0)+IF(J23=$M$7,1,0)+IF(K23=$M$7,1,0) | N23: =IF(G23=$N$7,1,0)+IF(H23=$N$7,1,0)+IF(I23=$N$7,1,0)+IF(J23=$N$7,1,0)+IF(K23=$N$7,1,0) | O23: =IF(G23=$O$7,1,0)+IF(H23=$O$7,1,0)+IF(I23=$O$7,1,0)+IF(J23=$O$7,1,0)+IF(K23=$O$7,1,0) | P23: =IF(G23=$P$7,1,0)+IF(H23=$P$7,1,0)+IF(I23=$P$7,1,0)+IF(J23=$P$7,1,0)+IF(K23=$P$7,1,0) | Q23: =IF(G23=$Q$7,1,0)+IF(H23=$Q$7,1,0)+IF(I23=$Q$7,1,0)+IF(J23=$Q$7,1,0)+IF(K23=$Q$7,1,0) | R23: =IF(G23=$R$7,1,0)+IF(H23=$R$7,1,0)+IF(I23=$R$7,1,0)+IF(J23=$R$7,1,0)+IF(K23=$R$7,1,0) | S23: =IF(G23=$S$7,1,0)+IF(H23=$S$7,1,0)+IF(I23=$S$7,1,0)+IF(J23=$S$7,1,0)+IF(K23=$S$7,1,0) | T23: =IF(G23=$T$7,1,0)+IF(H23=$T$7,1,0)+IF(I23=$T$7,1,0)+IF(J23=$T$7,1,0)+IF(K23=$T$7,1,0) | U23: =SUM(G23:K23) | V23: 24 | W23: =IF(U23-V23>0.1,1,0) | X23: =U23-V23 | Y23: 140
A24: 5 | C24: JVY420 | D24: L21 | E24: NHÀ XƯỞNG | F24: D300 | G24: 12 | H24: 12 | L24: =IF(G24=$L$7,1,0)+IF(H24=$L$7,1,0)+IF(I24=$L$7,1,0)+IF(J24=$L$7,1,0)+IF(K24=$L$7,1,0) | M24: =IF(G24=$M$7,1,0)+IF(H24=$M$7,1,0)+IF(I24=$M$7,1,0)+IF(J24=$M$7,1,0)+IF(K24=$M$7,1,0) | N24: =IF(G24=$N$7,1,0)+IF(H24=$N$7,1,0)+IF(I24=$N$7,1,0)+IF(J24=$N$7,1,0)+IF(K24=$N$7,1,0) | O24: =IF(G24=$O$7,1,0)+IF(H24=$O$7,1,0)+IF(I24=$O$7,1,0)+IF(J24=$O$7,1,0)+IF(K24=$O$7,1,0) | P24: =IF(G24=$P$7,1,0)+IF(H24=$P$7,1,0)+IF(I24=$P$7,1,0)+IF(J24=$P$7,1,0)+IF(K24=$P$7,1,0) | Q24: =IF(G24=$Q$7,1,0)+IF(H24=$Q$7,1,0)+IF(I24=$Q$7,1,0)+IF(J24=$Q$7,1,0)+IF(K24=$Q$7,1,0) | R24: =IF(G24=$R$7,1,0)+IF(H24=$R$7,1,0)+IF(I24=$R$7,1,0)+IF(J24=$R$7,1,0)+IF(K24=$R$7,1,0) | S24: =IF(G24=$S$7,1,0)+IF(H24=$S$7,1,0)+IF(I24=$S$7,1,0)+IF(J24=$S$7,1,0)+IF(K24=$S$7,1,0) | T24: =IF(G24=$T$7,1,0)+IF(H24=$T$7,1,0)+IF(I24=$T$7,1,0)+IF(J24=$T$7,1,0)+IF(K24=$T$7,1,0) | U24: =SUM(G24:K24) | V24: 24 | W24: =IF(U24-V24>0.1,1,0) | X24: =U24-V24 | Y24: 140
A25: 6 | C25: JVY420 | D25: L20 | E25: NHÀ XƯỞNG | F25: D300 | G25: 12 | H25: 12 | L25: =IF(G25=$L$7,1,0)+IF(H25=$L$7,1,0)+IF(I25=$L$7,1,0)+IF(J25=$L$7,1,0)+IF(K25=$L$7,1,0) | M25: =IF(G25=$M$7,1,0)+IF(H25=$M$7,1,0)+IF(I25=$M$7,1,0)+IF(J25=$M$7,1,0)+IF(K25=$M$7,1,0) | N25: =IF(G25=$N$7,1,0)+IF(H25=$N$7,1,0)+IF(I25=$N$7,1,0)+IF(J25=$N$7,1,0)+IF(K25=$N$7,1,0) | O25: =IF(G25=$O$7,1,0)+IF(H25=$O$7,1,0)+IF(I25=$O$7,1,0)+IF(J25=$O$7,1,0)+IF(K25=$O$7,1,0) | P25: =IF(G25=$P$7,1,0)+IF(H25=$P$7,1,0)+IF(I25=$P$7,1,0)+IF(J25=$P$7,1,0)+IF(K25=$P$7,1,0) | Q25: =IF(G25=$Q$7,1,0)+IF(H25=$Q$7,1,0)+IF(I25=$Q$7,1,0)+IF(J25=$Q$7,1,0)+IF(K25=$Q$7,1,0) | R25: =IF(G25=$R$7,1,0)+IF(H25=$R$7,1,0)+IF(I25=$R$7,1,0)+IF(J25=$R$7,1,0)+IF(K25=$R$7,1,0) | S25: =IF(G25=$S$7,1,0)+IF(H25=$S$7,1,0)+IF(I25=$S$7,1,0)+IF(J25=$S$7,1,0)+IF(K25=$S$7,1,0) | T25: =IF(G25=$T$7,1,0)+IF(H25=$T$7,1,0)+IF(I25=$T$7,1,0)+IF(J25=$T$7,1,0)+IF(K25=$T$7,1,0) | U25: =SUM(G25:K25) | V25: 24 | W25: =IF(U25-V25>0.1,1,0) | X25: =U25-V25 | Y25: 135
A26: 7 | C26: JVY420 | D26: L22 | E26: NHÀ XƯỞNG | F26: D300 | G26: 12 | H26: 12 | L26: =IF(G26=$L$7,1,0)+IF(H26=$L$7,1,0)+IF(I26=$L$7,1,0)+IF(J26=$L$7,1,0)+IF(K26=$L$7,1,0) | M26: =IF(G26=$M$7,1,0)+IF(H26=$M$7,1,0)+IF(I26=$M$7,1,0)+IF(J26=$M$7,1,0)+IF(K26=$M$7,1,0) | N26: =IF(G26=$N$7,1,0)+IF(H26=$N$7,1,0)+IF(I26=$N$7,1,0)+IF(J26=$N$7,1,0)+IF(K26=$N$7,1,0) | O26: =IF(G26=$O$7,1,0)+IF(H26=$O$7,1,0)+IF(I26=$O$7,1,0)+IF(J26=$O$7,1,0)+IF(K26=$O$7,1,0) | P26: =IF(G26=$P$7,1,0)+IF(H26=$P$7,1,0)+IF(I26=$P$7,1,0)+IF(J26=$P$7,1,0)+IF(K26=$P$7,1,0) | Q26: =IF(G26=$Q$7,1,0)+IF(H26=$Q$7,1,0)+IF(I26=$Q$7,1,0)+IF(J26=$Q$7,1,0)+IF(K26=$Q$7,1,0) | R26: =IF(G26=$R$7,1,0)+IF(H26=$R$7,1,0)+IF(I26=$R$7,1,0)+IF(J26=$R$7,1,0)+IF(K26=$R$7,1,0) | S26: =IF(G26=$S$7,1,0)+IF(H26=$S$7,1,0)+IF(I26=$S$7,1,0)+IF(J26=$S$7,1,0)+IF(K26=$S$7,1,0) | T26: =IF(G26=$T$7,1,0)+IF(H26=$T$7,1,0)+IF(I26=$T$7,1,0)+IF(J26=$T$7,1,0)+IF(K26=$T$7,1,0) | U26: =SUM(G26:K26) | V26: 24 | W26: =IF(U26-V26>0.1,1,0) | X26: =U26-V26 | Y26: 136
A27: 8 | C27: JVY420 | D27: L18 | E27: NHÀ XƯỞNG | F27: D300 | G27: 12 | H27: 12 | L27: =IF(G27=$L$7,1,0)+IF(H27=$L$7,1,0)+IF(I27=$L$7,1,0)+IF(J27=$L$7,1,0)+IF(K27=$L$7,1,0) | M27: =IF(G27=$M$7,1,0)+IF(H27=$M$7,1,0)+IF(I27=$M$7,1,0)+IF(J27=$M$7,1,0)+IF(K27=$M$7,1,0) | N27: =IF(G27=$N$7,1,0)+IF(H27=$N$7,1,0)+IF(I27=$N$7,1,0)+IF(J27=$N$7,1,0)+IF(K27=$N$7,1,0) | O27: =IF(G27=$O$7,1,0)+IF(H27=$O$7,1,0)+IF(I27=$O$7,1,0)+IF(J27=$O$7,1,0)+IF(K27=$O$7,1,0) | P27: =IF(G27=$P$7,1,0)+IF(H27=$P$7,1,0)+IF(I27=$P$7,1,0)+IF(J27=$P$7,1,0)+IF(K27=$P$7,1,0) | Q27: =IF(G27=$Q$7,1,0)+IF(H27=$Q$7,1,0)+IF(I27=$Q$7,1,0)+IF(J27=$Q$7,1,0)+IF(K27=$Q$7,1,0) | R27: =IF(G27=$R$7,1,0)+IF(H27=$R$7,1,0)+IF(I27=$R$7,1,0)+IF(J27=$R$7,1,0)+IF(K27=$R$7,1,0) | S27: =IF(G27=$S$7,1,0)+IF(H27=$S$7,1,0)+IF(I27=$S$7,1,0)+IF(J27=$S$7,1,0)+IF(K27=$S$7,1,0) | T27: =IF(G27=$T$7,1,0)+IF(H27=$T$7,1,0)+IF(I27=$T$7,1,0)+IF(J27=$T$7,1,0)+IF(K27=$T$7,1,0) | U27: =SUM(G27:K27) | V27: 24 | W27: =IF(U27-V27>0.1,1,0) | X27: =U27-V27 | Y27: 135
A28: 9 | C28: JVY420 | D28: L16 | E28: NHÀ XƯỞNG | F28: D300 | G28: 12 | H28: 12 | L28: =IF(G28=$L$7,1,0)+IF(H28=$L$7,1,0)+IF(I28=$L$7,1,0)+IF(J28=$L$7,1,0)+IF(K28=$L$7,1,0) | M28: =IF(G28=$M$7,1,0)+IF(H28=$M$7,1,0)+IF(I28=$M$7,1,0)+IF(J28=$M$7,1,0)+IF(K28=$M$7,1,0) | N28: =IF(G28=$N$7,1,0)+IF(H28=$N$7,1,0)+IF(I28=$N$7,1,0)+IF(J28=$N$7,1,0)+IF(K28=$N$7,1,0) | O28: =IF(G28=$O$7,1,0)+IF(H28=$O$7,1,0)+IF(I28=$O$7,1,0)+IF(J28=$O$7,1,0)+IF(K28=$O$7,1,0) | P28: =IF(G28=$P$7,1,0)+IF(H28=$P$7,1,0)+IF(I28=$P$7,1,0)+IF(J28=$P$7,1,0)+IF(K28=$P$7,1,0) | Q28: =IF(G28=$Q$7,1,0)+IF(H28=$Q$7,1,0)+IF(I28=$Q$7,1,0)+IF(J28=$Q$7,1,0)+IF(K28=$Q$7,1,0) | R28: =IF(G28=$R$7,1,0)+IF(H28=$R$7,1,0)+IF(I28=$R$7,1,0)+IF(J28=$R$7,1,0)+IF(K28=$R$7,1,0) | S28: =IF(G28=$S$7,1,0)+IF(H28=$S$7,1,0)+IF(I28=$S$7,1,0)+IF(J28=$S$7,1,0)+IF(K28=$S$7,1,0) | T28: =IF(G28=$T$7,1,0)+IF(H28=$T$7,1,0)+IF(I28=$T$7,1,0)+IF(J28=$T$7,1,0)+IF(K28=$T$7,1,0) | U28: =SUM(G28:K28) | V28: 24 | W28: =IF(U28-V28>0.1,1,0) | X28: =U28-V28 | Y28: 136
A29: 10 | C29: JVY420 | D29: L14 | E29: NHÀ XƯỞNG | F29: D300 | G29: 12 | H29: 12 | L29: =IF(G29=$L$7,1,0)+IF(H29=$L$7,1,0)+IF(I29=$L$7,1,0)+IF(J29=$L$7,1,0)+IF(K29=$L$7,1,0) | M29: =IF(G29=$M$7,1,0)+IF(H29=$M$7,1,0)+IF(I29=$M$7,1,0)+IF(J29=$M$7,1,0)+IF(K29=$M$7,1,0) | N29: =IF(G29=$N$7,1,0)+IF(H29=$N$7,1,0)+IF(I29=$N$7,1,0)+IF(J29=$N$7,1,0)+IF(K29=$N$7,1,0) | O29: =IF(G29=$O$7,1,0)+IF(H29=$O$7,1,0)+IF(I29=$O$7,1,0)+IF(J29=$O$7,1,0)+IF(K29=$O$7,1,0) | P29: =IF(G29=$P$7,1,0)+IF(H29=$P$7,1,0)+IF(I29=$P$7,1,0)+IF(J29=$P$7,1,0)+IF(K29=$P$7,1,0) | Q29: =IF(G29=$Q$7,1,0)+IF(H29=$Q$7,1,0)+IF(I29=$Q$7,1,0)+IF(J29=$Q$7,1,0)+IF(K29=$Q$7,1,0) | R29: =IF(G29=$R$7,1,0)+IF(H29=$R$7,1,0)+IF(I29=$R$7,1,0)+IF(J29=$R$7,1,0)+IF(K29=$R$7,1,0) | S29: =IF(G29=$S$7,1,0)+IF(H29=$S$7,1,0)+IF(I29=$S$7,1,0)+IF(J29=$S$7,1,0)+IF(K29=$S$7,1,0) | T29: =IF(G29=$T$7,1,0)+IF(H29=$T$7,1,0)+IF(I29=$T$7,1,0)+IF(J29=$T$7,1,0)+IF(K29=$T$7,1,0) | U29: =SUM(G29:K29) | V29: 24 | W29: =IF(U29-V29>0.1,1,0) | X29: =U29-V29 | Y29: 140
A30: 11 | C30: JVY420 | D30: L12 | E30: NHÀ XƯỞNG | F30: D300 | G30: 12 | H30: 12 | L30: =IF(G30=$L$7,1,0)+IF(H30=$L$7,1,0)+IF(I30=$L$7,1,0)+IF(J30=$L$7,1,0)+IF(K30=$L$7,1,0) | M30: =IF(G30=$M$7,1,0)+IF(H30=$M$7,1,0)+IF(I30=$M$7,1,0)+IF(J30=$M$7,1,0)+IF(K30=$M$7,1,0) | N30: =IF(G30=$N$7,1,0)+IF(H30=$N$7,1,0)+IF(I30=$N$7,1,0)+IF(J30=$N$7,1,0)+IF(K30=$N$7,1,0) | O30: =IF(G30=$O$7,1,0)+IF(H30=$O$7,1,0)+IF(I30=$O$7,1,0)+IF(J30=$O$7,1,0)+IF(K30=$O$7,1,0) | P30: =IF(G30=$P$7,1,0)+IF(H30=$P$7,1,0)+IF(I30=$P$7,1,0)+IF(J30=$P$7,1,0)+IF(K30=$P$7,1,0) | Q30: =IF(G30=$Q$7,1,0)+IF(H30=$Q$7,1,0)+IF(I30=$Q$7,1,0)+IF(J30=$Q$7,1,0)+IF(K30=$Q$7,1,0) | R30: =IF(G30=$R$7,1,0)+IF(H30=$R$7,1,0)+IF(I30=$R$7,1,0)+IF(J30=$R$7,1,0)+IF(K30=$R$7,1,0) | S30: =IF(G30=$S$7,1,0)+IF(H30=$S$7,1,0)+IF(I30=$S$7,1,0)+IF(J30=$S$7,1,0)+IF(K30=$S$7,1,0) | T30: =IF(G30=$T$7,1,0)+IF(H30=$T$7,1,0)+IF(I30=$T$7,1,0)+IF(J30=$T$7,1,0)+IF(K30=$T$7,1,0) | U30: =SUM(G30:K30) | V30: 24 | W30: =IF(U30-V30>0.1,1,0) | X30: =U30-V30 | Y30: 150
A31: 12 | B31: 46082 | C31: JVY420 | D31: L10 | E31: NHÀ XƯỞNG | F31: D300 | G31: 13 | H31: 12 | L31: =IF(G31=$L$7,1,0)+IF(H31=$L$7,1,0)+IF(I31=$L$7,1,0)+IF(J31=$L$7,1,0)+IF(K31=$L$7,1,0) | M31: =IF(G31=$M$7,1,0)+IF(H31=$M$7,1,0)+IF(I31=$M$7,1,0)+IF(J31=$M$7,1,0)+IF(K31=$M$7,1,0) | N31: =IF(G31=$N$7,1,0)+IF(H31=$N$7,1,0)+IF(I31=$N$7,1,0)+IF(J31=$N$7,1,0)+IF(K31=$N$7,1,0) | O31: =IF(G31=$O$7,1,0)+IF(H31=$O$7,1,0)+IF(I31=$O$7,1,0)+IF(J31=$O$7,1,0)+IF(K31=$O$7,1,0) | P31: =IF(G31=$P$7,1,0)+IF(H31=$P$7,1,0)+IF(I31=$P$7,1,0)+IF(J31=$P$7,1,0)+IF(K31=$P$7,1,0) | Q31: =IF(G31=$Q$7,1,0)+IF(H31=$Q$7,1,0)+IF(I31=$Q$7,1,0)+IF(J31=$Q$7,1,0)+IF(K31=$Q$7,1,0) | R31: =IF(G31=$R$7,1,0)+IF(H31=$R$7,1,0)+IF(I31=$R$7,1,0)+IF(J31=$R$7,1,0)+IF(K31=$R$7,1,0) | S31: =IF(G31=$S$7,1,0)+IF(H31=$S$7,1,0)+IF(I31=$S$7,1,0)+IF(J31=$S$7,1,0)+IF(K31=$S$7,1,0) | T31: =IF(G31=$T$7,1,0)+IF(H31=$T$7,1,0)+IF(I31=$T$7,1,0)+IF(J31=$T$7,1,0)+IF(K31=$T$7,1,0) | U31: =SUM(G31:K31) | V31: 25 | W31: =IF(U31-V31>0.1,1,0) | X31: =U31-V31 | Y31: 150
A32: 13 | C32: JVY420 | D32: L8 | E32: NHÀ XƯỞNG | F32: D300 | G32: 13 | H32: 10 | L32: =IF(G32=$L$7,1,0)+IF(H32=$L$7,1,0)+IF(I32=$L$7,1,0)+IF(J32=$L$7,1,0)+IF(K32=$L$7,1,0) | M32: =IF(G32=$M$7,1,0)+IF(H32=$M$7,1,0)+IF(I32=$M$7,1,0)+IF(J32=$M$7,1,0)+IF(K32=$M$7,1,0) | N32: =IF(G32=$N$7,1,0)+IF(H32=$N$7,1,0)+IF(I32=$N$7,1,0)+IF(J32=$N$7,1,0)+IF(K32=$N$7,1,0) | O32: =IF(G32=$O$7,1,0)+IF(H32=$O$7,1,0)+IF(I32=$O$7,1,0)+IF(J32=$O$7,1,0)+IF(K32=$O$7,1,0) | P32: =IF(G32=$P$7,1,0)+IF(H32=$P$7,1,0)+IF(I32=$P$7,1,0)+IF(J32=$P$7,1,0)+IF(K32=$P$7,1,0) | Q32: =IF(G32=$Q$7,1,0)+IF(H32=$Q$7,1,0)+IF(I32=$Q$7,1,0)+IF(J32=$Q$7,1,0)+IF(K32=$Q$7,1,0) | R32: =IF(G32=$R$7,1,0)+IF(H32=$R$7,1,0)+IF(I32=$R$7,1,0)+IF(J32=$R$7,1,0)+IF(K32=$R$7,1,0) | S32: =IF(G32=$S$7,1,0)+IF(H32=$S$7,1,0)+IF(I32=$S$7,1,0)+IF(J32=$S$7,1,0)+IF(K32=$S$7,1,0) | T32: =IF(G32=$T$7,1,0)+IF(H32=$T$7,1,0)+IF(I32=$T$7,1,0)+IF(J32=$T$7,1,0)+IF(K32=$T$7,1,0) | U32: =SUM(G32:K32) | V32: 23 | W32: =IF(U32-V32>0.1,1,0) | X32: =U32-V32 | Y32: 135
A33: 14 | C33: JVY420 | D33: L6 | E33: NHÀ XƯỞNG | F33: D300 | G33: 12 | H33: 12 | L33: =IF(G33=$L$7,1,0)+IF(H33=$L$7,1,0)+IF(I33=$L$7,1,0)+IF(J33=$L$7,1,0)+IF(K33=$L$7,1,0) | M33: =IF(G33=$M$7,1,0)+IF(H33=$M$7,1,0)+IF(I33=$M$7,1,0)+IF(J33=$M$7,1,0)+IF(K33=$M$7,1,0) | N33: =IF(G33=$N$7,1,0)+IF(H33=$N$7,1,0)+IF(I33=$N$7,1,0)+IF(J33=$N$7,1,0)+IF(K33=$N$7,1,0) | O33: =IF(G33=$O$7,1,0)+IF(H33=$O$7,1,0)+IF(I33=$O$7,1,0)+IF(J33=$O$7,1,0)+IF(K33=$O$7,1,0) | P33: =IF(G33=$P$7,1,0)+IF(H33=$P$7,1,0)+IF(I33=$P$7,1,0)+IF(J33=$P$7,1,0)+IF(K33=$P$7,1,0) | Q33: =IF(G33=$Q$7,1,0)+IF(H33=$Q$7,1,0)+IF(I33=$Q$7,1,0)+IF(J33=$Q$7,1,0)+IF(K33=$Q$7,1,0) | R33: =IF(G33=$R$7,1,0)+IF(H33=$R$7,1,0)+IF(I33=$R$7,1,0)+IF(J33=$R$7,1,0)+IF(K33=$R$7,1,0) | S33: =IF(G33=$S$7,1,0)+IF(H33=$S$7,1,0)+IF(I33=$S$7,1,0)+IF(J33=$S$7,1,0)+IF(K33=$S$7,1,0) | T33: =IF(G33=$T$7,1,0)+IF(H33=$T$7,1,0)+IF(I33=$T$7,1,0)+IF(J33=$T$7,1,0)+IF(K33=$T$7,1,0) | U33: =SUM(G33:K33) | V33: 24 | W33: =IF(U33-V33>0.1,1,0) | X33: =U33-V33 | Y33: 140
A34: 15 | C34: JVY420 | D34: L4 | E34: NHÀ XƯỞNG | F34: D300 | G34: 12 | H34: 12 | L34: =IF(G34=$L$7,1,0)+IF(H34=$L$7,1,0)+IF(I34=$L$7,1,0)+IF(J34=$L$7,1,0)+IF(K34=$L$7,1,0) | M34: =IF(G34=$M$7,1,0)+IF(H34=$M$7,1,0)+IF(I34=$M$7,1,0)+IF(J34=$M$7,1,0)+IF(K34=$M$7,1,0) | N34: =IF(G34=$N$7,1,0)+IF(H34=$N$7,1,0)+IF(I34=$N$7,1,0)+IF(J34=$N$7,1,0)+IF(K34=$N$7,1,0) | O34: =IF(G34=$O$7,1,0)+IF(H34=$O$7,1,0)+IF(I34=$O$7,1,0)+IF(J34=$O$7,1,0)+IF(K34=$O$7,1,0) | P34: =IF(G34=$P$7,1,0)+IF(H34=$P$7,1,0)+IF(I34=$P$7,1,0)+IF(J34=$P$7,1,0)+IF(K34=$P$7,1,0) | Q34: =IF(G34=$Q$7,1,0)+IF(H34=$Q$7,1,0)+IF(I34=$Q$7,1,0)+IF(J34=$Q$7,1,0)+IF(K34=$Q$7,1,0) | R34: =IF(G34=$R$7,1,0)+IF(H34=$R$7,1,0)+IF(I34=$R$7,1,0)+IF(J34=$R$7,1,0)+IF(K34=$R$7,1,0) | S34: =IF(G34=$S$7,1,0)+IF(H34=$S$7,1,0)+IF(I34=$S$7,1,0)+IF(J34=$S$7,1,0)+IF(K34=$S$7,1,0) | T34: =IF(G34=$T$7,1,0)+IF(H34=$T$7,1,0)+IF(I34=$T$7,1,0)+IF(J34=$T$7,1,0)+IF(K34=$T$7,1,0) | U34: =SUM(G34:K34) | V34: 24 | W34: =IF(U34-V34>0.1,1,0) | X34: =U34-V34 | Y34: 140
A35: 16 | C35: JVY420 | D35: L2 | E35: NHÀ XƯỞNG | F35: D300 | G35: 12 | H35: 12 | L35: =IF(G35=$L$7,1,0)+IF(H35=$L$7,1,0)+IF(I35=$L$7,1,0)+IF(J35=$L$7,1,0)+IF(K35=$L$7,1,0) | M35: =IF(G35=$M$7,1,0)+IF(H35=$M$7,1,0)+IF(I35=$M$7,1,0)+IF(J35=$M$7,1,0)+IF(K35=$M$7,1,0) | N35: =IF(G35=$N$7,1,0)+IF(H35=$N$7,1,0)+IF(I35=$N$7,1,0)+IF(J35=$N$7,1,0)+IF(K35=$N$7,1,0) | O35: =IF(G35=$O$7,1,0)+IF(H35=$O$7,1,0)+IF(I35=$O$7,1,0)+IF(J35=$O$7,1,0)+IF(K35=$O$7,1,0) | P35: =IF(G35=$P$7,1,0)+IF(H35=$P$7,1,0)+IF(I35=$P$7,1,0)+IF(J35=$P$7,1,0)+IF(K35=$P$7,1,0) | Q35: =IF(G35=$Q$7,1,0)+IF(H35=$Q$7,1,0)+IF(I35=$Q$7,1,0)+IF(J35=$Q$7,1,0)+IF(K35=$Q$7,1,0) | R35: =IF(G35=$R$7,1,0)+IF(H35=$R$7,1,0)+IF(I35=$R$7,1,0)+IF(J35=$R$7,1,0)+IF(K35=$R$7,1,0) | S35: =IF(G35=$S$7,1,0)+IF(H35=$S$7,1,0)+IF(I35=$S$7,1,0)+IF(J35=$S$7,1,0)+IF(K35=$S$7,1,0) | T35: =IF(G35=$T$7,1,0)+IF(H35=$T$7,1,0)+IF(I35=$T$7,1,0)+IF(J35=$T$7,1,0)+IF(K35=$T$7,1,0) | U35: =SUM(G35:K35) | V35: 24 | W35: =IF(U35-V35>0.1,1,0) | X35: =U35-V35 | Y35: 140
A36: 17 | C36: JVY420 | D36: L1 | E36: NHÀ XƯỞNG | F36: D300 | G36: 12 | H36: 12 | L36: =IF(G36=$L$7,1,0)+IF(H36=$L$7,1,0)+IF(I36=$L$7,1,0)+IF(J36=$L$7,1,0)+IF(K36=$L$7,1,0) | M36: =IF(G36=$M$7,1,0)+IF(H36=$M$7,1,0)+IF(I36=$M$7,1,0)+IF(J36=$M$7,1,0)+IF(K36=$M$7,1,0) | N36: =IF(G36=$N$7,1,0)+IF(H36=$N$7,1,0)+IF(I36=$N$7,1,0)+IF(J36=$N$7,1,0)+IF(K36=$N$7,1,0) | O36: =IF(G36=$O$7,1,0)+IF(H36=$O$7,1,0)+IF(I36=$O$7,1,0)+IF(J36=$O$7,1,0)+IF(K36=$O$7,1,0) | P36: =IF(G36=$P$7,1,0)+IF(H36=$P$7,1,0)+IF(I36=$P$7,1,0)+IF(J36=$P$7,1,0)+IF(K36=$P$7,1,0) | Q36: =IF(G36=$Q$7,1,0)+IF(H36=$Q$7,1,0)+IF(I36=$Q$7,1,0)+IF(J36=$Q$7,1,0)+IF(K36=$Q$7,1,0) | R36: =IF(G36=$R$7,1,0)+IF(H36=$R$7,1,0)+IF(I36=$R$7,1,0)+IF(J36=$R$7,1,0)+IF(K36=$R$7,1,0) | S36: =IF(G36=$S$7,1,0)+IF(H36=$S$7,1,0)+IF(I36=$S$7,1,0)+IF(J36=$S$7,1,0)+IF(K36=$S$7,1,0) | T36: =IF(G36=$T$7,1,0)+IF(H36=$T$7,1,0)+IF(I36=$T$7,1,0)+IF(J36=$T$7,1,0)+IF(K36=$T$7,1,0) | U36: =SUM(G36:K36) | V36: 24 | W36: =IF(U36-V36>0.1,1,0) | X36: =U36-V36 | Y36: 140
A37: 18 | C37: JVY420 | D37: L5 | E37: NHÀ XƯỞNG | F37: D300 | G37: 12 | H37: 12 | L37: =IF(G37=$L$7,1,0)+IF(H37=$L$7,1,0)+IF(I37=$L$7,1,0)+IF(J37=$L$7,1,0)+IF(K37=$L$7,1,0) | M37: =IF(G37=$M$7,1,0)+IF(H37=$M$7,1,0)+IF(I37=$M$7,1,0)+IF(J37=$M$7,1,0)+IF(K37=$M$7,1,0) | N37: =IF(G37=$N$7,1,0)+IF(H37=$N$7,1,0)+IF(I37=$N$7,1,0)+IF(J37=$N$7,1,0)+IF(K37=$N$7,1,0) | O37: =IF(G37=$O$7,1,0)+IF(H37=$O$7,1,0)+IF(I37=$O$7,1,0)+IF(J37=$O$7,1,0)+IF(K37=$O$7,1,0) | P37: =IF(G37=$P$7,1,0)+IF(H37=$P$7,1,0)+IF(I37=$P$7,1,0)+IF(J37=$P$7,1,0)+IF(K37=$P$7,1,0) | Q37: =IF(G37=$Q$7,1,0)+IF(H37=$Q$7,1,0)+IF(I37=$Q$7,1,0)+IF(J37=$Q$7,1,0)+IF(K37=$Q$7,1,0) | R37: =IF(G37=$R$7,1,0)+IF(H37=$R$7,1,0)+IF(I37=$R$7,1,0)+IF(J37=$R$7,1,0)+IF(K37=$R$7,1,0) | S37: =IF(G37=$S$7,1,0)+IF(H37=$S$7,1,0)+IF(I37=$S$7,1,0)+IF(J37=$S$7,1,0)+IF(K37=$S$7,1,0) | T37: =IF(G37=$T$7,1,0)+IF(H37=$T$7,1,0)+IF(I37=$T$7,1,0)+IF(J37=$T$7,1,0)+IF(K37=$T$7,1,0) | U37: =SUM(G37:K37) | V37: 24 | W37: =IF(U37-V37>0.1,1,0) | X37: =U37-V37 | Y37: 140
A38: 19 | C38: JVY420 | D38: L3 | E38: NHÀ XƯỞNG | F38: D300 | G38: 12 | H38: 11 | L38: =IF(G38=$L$7,1,0)+IF(H38=$L$7,1,0)+IF(I38=$L$7,1,0)+IF(J38=$L$7,1,0)+IF(K38=$L$7,1,0) | M38: =IF(G38=$M$7,1,0)+IF(H38=$M$7,1,0)+IF(I38=$M$7,1,0)+IF(J38=$M$7,1,0)+IF(K38=$M$7,1,0) | N38: =IF(G38=$N$7,1,0)+IF(H38=$N$7,1,0)+IF(I38=$N$7,1,0)+IF(J38=$N$7,1,0)+IF(K38=$N$7,1,0) | O38: =IF(G38=$O$7,1,0)+IF(H38=$O$7,1,0)+IF(I38=$O$7,1,0)+IF(J38=$O$7,1,0)+IF(K38=$O$7,1,0) | P38: =IF(G38=$P$7,1,0)+IF(H38=$P$7,1,0)+IF(I38=$P$7,1,0)+IF(J38=$P$7,1,0)+IF(K38=$P$7,1,0) | Q38: =IF(G38=$Q$7,1,0)+IF(H38=$Q$7,1,0)+IF(I38=$Q$7,1,0)+IF(J38=$Q$7,1,0)+IF(K38=$Q$7,1,0) | R38: =IF(G38=$R$7,1,0)+IF(H38=$R$7,1,0)+IF(I38=$R$7,1,0)+IF(J38=$R$7,1,0)+IF(K38=$R$7,1,0) | S38: =IF(G38=$S$7,1,0)+IF(H38=$S$7,1,0)+IF(I38=$S$7,1,0)+IF(J38=$S$7,1,0)+IF(K38=$S$7,1,0) | T38: =IF(G38=$T$7,1,0)+IF(H38=$T$7,1,0)+IF(I38=$T$7,1,0)+IF(J38=$T$7,1,0)+IF(K38=$T$7,1,0) | U38: =SUM(G38:K38) | V38: 23 | W38: =IF(U38-V38>0.1,1,0) | X38: =U38-V38 | Y38: 136
A39: 20 | C39: JVY420 | D39: L7 | E39: NHÀ XƯỞNG | F39: D300 | G39: 12 | H39: 11 | L39: =IF(G39=$L$7,1,0)+IF(H39=$L$7,1,0)+IF(I39=$L$7,1,0)+IF(J39=$L$7,1,0)+IF(K39=$L$7,1,0) | M39: =IF(G39=$M$7,1,0)+IF(H39=$M$7,1,0)+IF(I39=$M$7,1,0)+IF(J39=$M$7,1,0)+IF(K39=$M$7,1,0) | N39: =IF(G39=$N$7,1,0)+IF(H39=$N$7,1,0)+IF(I39=$N$7,1,0)+IF(J39=$N$7,1,0)+IF(K39=$N$7,1,0) | O39: =IF(G39=$O$7,1,0)+IF(H39=$O$7,1,0)+IF(I39=$O$7,1,0)+IF(J39=$O$7,1,0)+IF(K39=$O$7,1,0) | P39: =IF(G39=$P$7,1,0)+IF(H39=$P$7,1,0)+IF(I39=$P$7,1,0)+IF(J39=$P$7,1,0)+IF(K39=$P$7,1,0) | Q39: =IF(G39=$Q$7,1,0)+IF(H39=$Q$7,1,0)+IF(I39=$Q$7,1,0)+IF(J39=$Q$7,1,0)+IF(K39=$Q$7,1,0) | R39: =IF(G39=$R$7,1,0)+IF(H39=$R$7,1,0)+IF(I39=$R$7,1,0)+IF(J39=$R$7,1,0)+IF(K39=$R$7,1,0) | S39: =IF(G39=$S$7,1,0)+IF(H39=$S$7,1,0)+IF(I39=$S$7,1,0)+IF(J39=$S$7,1,0)+IF(K39=$S$7,1,0) | T39: =IF(G39=$T$7,1,0)+IF(H39=$T$7,1,0)+IF(I39=$T$7,1,0)+IF(J39=$T$7,1,0)+IF(K39=$T$7,1,0) | U39: =SUM(G39:K39) | V39: 23 | W39: =IF(U39-V39>0.1,1,0) | X39: =U39-V39 | Y39: 136
A40: 21 | C40: JVY420 | D40: L11 | E40: NHÀ XƯỞNG | F40: D300 | G40: 12 | H40: 11 | L40: =IF(G40=$L$7,1,0)+IF(H40=$L$7,1,0)+IF(I40=$L$7,1,0)+IF(J40=$L$7,1,0)+IF(K40=$L$7,1,0) | M40: =IF(G40=$M$7,1,0)+IF(H40=$M$7,1,0)+IF(I40=$M$7,1,0)+IF(J40=$M$7,1,0)+IF(K40=$M$7,1,0) | N40: =IF(G40=$N$7,1,0)+IF(H40=$N$7,1,0)+IF(I40=$N$7,1,0)+IF(J40=$N$7,1,0)+IF(K40=$N$7,1,0) | O40: =IF(G40=$O$7,1,0)+IF(H40=$O$7,1,0)+IF(I40=$O$7,1,0)+IF(J40=$O$7,1,0)+IF(K40=$O$7,1,0) | P40: =IF(G40=$P$7,1,0)+IF(H40=$P$7,1,0)+IF(I40=$P$7,1,0)+IF(J40=$P$7,1,0)+IF(K40=$P$7,1,0) | Q40: =IF(G40=$Q$7,1,0)+IF(H40=$Q$7,1,0)+IF(I40=$Q$7,1,0)+IF(J40=$Q$7,1,0)+IF(K40=$Q$7,1,0) | R40: =IF(G40=$R$7,1,0)+IF(H40=$R$7,1,0)+IF(I40=$R$7,1,0)+IF(J40=$R$7,1,0)+IF(K40=$R$7,1,0) | S40: =IF(G40=$S$7,1,0)+IF(H40=$S$7,1,0)+IF(I40=$S$7,1,0)+IF(J40=$S$7,1,0)+IF(K40=$S$7,1,0) | T40: =IF(G40=$T$7,1,0)+IF(H40=$T$7,1,0)+IF(I40=$T$7,1,0)+IF(J40=$T$7,1,0)+IF(K40=$T$7,1,0) | U40: =SUM(G40:K40) | V40: 23 | W40: =IF(U40-V40>0.1,1,0) | X40: =U40-V40 | Y40: 136
A41: 22 | C41: JVY420 | D41: L15 | E41: NHÀ XƯỞNG | F41: D300 | G41: 12 | H41: 12 | L41: =IF(G41=$L$7,1,0)+IF(H41=$L$7,1,0)+IF(I41=$L$7,1,0)+IF(J41=$L$7,1,0)+IF(K41=$L$7,1,0) | M41: =IF(G41=$M$7,1,0)+IF(H41=$M$7,1,0)+IF(I41=$M$7,1,0)+IF(J41=$M$7,1,0)+IF(K41=$M$7,1,0) | N41: =IF(G41=$N$7,1,0)+IF(H41=$N$7,1,0)+IF(I41=$N$7,1,0)+IF(J41=$N$7,1,0)+IF(K41=$N$7,1,0) | O41: =IF(G41=$O$7,1,0)+IF(H41=$O$7,1,0)+IF(I41=$O$7,1,0)+IF(J41=$O$7,1,0)+IF(K41=$O$7,1,0) | P41: =IF(G41=$P$7,1,0)+IF(H41=$P$7,1,0)+IF(I41=$P$7,1,0)+IF(J41=$P$7,1,0)+IF(K41=$P$7,1,0) | Q41: =IF(G41=$Q$7,1,0)+IF(H41=$Q$7,1,0)+IF(I41=$Q$7,1,0)+IF(J41=$Q$7,1,0)+IF(K41=$Q$7,1,0) | R41: =IF(G41=$R$7,1,0)+IF(H41=$R$7,1,0)+IF(I41=$R$7,1,0)+IF(J41=$R$7,1,0)+IF(K41=$R$7,1,0) | S41: =IF(G41=$S$7,1,0)+IF(H41=$S$7,1,0)+IF(I41=$S$7,1,0)+IF(J41=$S$7,1,0)+IF(K41=$S$7,1,0) | T41: =IF(G41=$T$7,1,0)+IF(H41=$T$7,1,0)+IF(I41=$T$7,1,0)+IF(J41=$T$7,1,0)+IF(K41=$T$7,1,0) | U41: =SUM(G41:K41) | V41: 24 | W41: =IF(U41-V41>0.1,1,0) | X41: =U41-V41 | Y41: 140
...

Sheet nhập cọc D350
B1: BẢNG THỐNG KÊ KHỐI LƯỢNG CỌC NHẬP VỀ
B3: STT | C3: Ngày xuất | D3: Số phiếu | E3: Chủng loại PHC-A350 | N3: Xe vận chuyển | O3: ="Tổng số m cọc D"&E4 | P3: đơn vị | Q3: Ghi chú
E4: D400
E5: 6 | F5: 7 | G5: 8 | H5: 9 | I5: 10 | J5: 11 | K5: 12 | L5: 13 | M5: 14
B6: 1 | C6: 46041 | D6: 2600357 | L6: 9 | O6: =E6*$E$5+F6*$F$5+G6*$G$5+H6*$H$5+I6*$I$5+J6*$J$5+K6*$K$5+L6*$L$5+M6*$M$5 | P6: TRƯỜNG SƠN
B7: 2 | C7: 46083 | D7: 1631 | L7: 24 | O7: =E7*$E$5+F7*$F$5+G7*$G$5+H7*$H$5+I7*$I$5+J7*$J$5+K7*$K$5+L7*$L$5+M7*$M$5 | P7: PETRO
B8: 3 | D8: 1633 | L8: 24 | O8: =E8*$E$5+F8*$F$5+G8*$G$5+H8*$H$5+I8*$I$5+J8*$J$5+K8*$K$5+L8*$L$5+M8*$M$5 | P8: PETRO
O9: =E9*$E$5+F9*$F$5+G9*$G$5+H9*$H$5+I9*$I$5+J9*$J$5+K9*$K$5+L9*$L$5+M9*$M$5
B10: 50 | O10: =E10*$E$5+F10*$F$5+G10*$G$5+H10*$H$5+I10*$I$5+J10*$J$5+K10*$K$5+L10*$L$5+M10*$M$5
B11: 51 | O11: =E11*$E$5+F11*$F$5+G11*$G$5+H11*$H$5+I11*$I$5+J11*$J$5+K11*$K$5+L11*$L$5+M11*$M$5
B12: KL CỌC NHẬP VỀ | E12: =SUM(E6:E11) | F12: =SUM(F6:F11) | G12: =SUM(G6:G11) | H12: =SUM(H6:H11) | I12: =SUM(I6:I11) | J12: =SUM(J6:J11) | K12: =SUM(K6:K11) | L12: =SUM(L6:L11) | M12: =SUM(M6:M11) | N12: =SUM(E12:M12) | O12: =SUM(O6:O11)
B13: KL CỌC THI CÔNG | E13: ='ÉP D350'!L10 | F13: ='ÉP D350'!M10 | G13: ='ÉP D350'!N10 | H13: ='ÉP D350'!O10 | I13: ='ÉP D350'!P10 | J13: ='ÉP D350'!Q10 | K13: ='ÉP D350'!R23 | L13: ='ÉP D350'!S23 | M13: ='ÉP D350'!T23 | N13: =J13+L13
B14: KL CỌC LOẠI
B15: KL CỌC CÒN LẠI | E15: =E12-E13-E14 | F15: =F12-F13-F14 | G15: =G12-G13-G14 | H15: =H12-H13-H14 | I15: =I12-I13-I14 | J15: =J12-J13-J14 | K15: =K12-K13-K14 | L15: =L12-L13-L14 | M15: =M12-M13-M14
B17: MAIN CONTRACTOR / NHÀ THẦU CHÍNH | L17: SUBCONTRACTORS / NHÀ THẦU PHỤ

Sheet nhập cọc D300
B1: BẢNG THỐNG KÊ KHỐI LƯỢNG CỌC NHẬP VỀ
B3: STT | C3: Ngày xuất | D3: Số phiếu | E3: Chủng loại PHC-A300 | N3: Xe vận chuyển | O3: ="Tổng số m cọc D"&E4 | P3: đơn vị | Q3: Ghi chú
E4: D400
E5: 6 | F5: 7 | G5: 8 | H5: 9 | I5: 10 | J5: 11 | K5: 12 | L5: 13 | M5: 14
B6: 1 | C6: 46042 | D6: 2600373 | I6: 10 | L6: 23 | O6: =E6*$E$5+F6*$F$5+G6*$G$5+H6*$H$5+I6*$I$5+J6*$J$5+K6*$K$5+L6*$L$5+M6*$M$5 | P6: TRƯỜNG SƠN
B7: 2 | C7: 46059 | D7: 2600664 | I7: 17 | J7: 3 | K7: 12 | L7: 3 | O7: =E7*$E$5+F7*$F$5+G7*$G$5+H7*$H$5+I7*$I$5+J7*$J$5+K7*$K$5+L7*$L$5+M7*$M$5 | P7: TRƯỜNG SƠN
B8: 3 | C8: 46079 | D8: 1500 | K8: 30 | O8: =E8*$E$5+F8*$F$5+G8*$G$5+H8*$H$5+I8*$I$5+J8*$J$5+K8*$K$5+L8*$L$5+M8*$M$5 | P8: PETRO
B9: 4 | D9: 1494 | K9: 30 | O9: =E9*$E$5+F9*$F$5+G9*$G$5+H9*$H$5+I9*$I$5+J9*$J$5+K9*$K$5+L9*$L$5+M9*$M$5 | P9: PETRO
B10: 5 | D10: 1499 | K10: 30 | O10: =E10*$E$5+F10*$F$5+G10*$G$5+H10*$H$5+I10*$I$5+J10*$J$5+K10*$K$5+L10*$L$5+M10*$M$5 | P10: PETRO
B11: 8 | C11: 46080 | D11: 1524 | K11: 30 | O11: =E11*$E$5+F11*$F$5+G11*$G$5+H11*$H$5+I11*$I$5+J11*$J$5+K11*$K$5+L11*$L$5+M11*$M$5 | P11: PETRO
B12: 10 | C12: 46082 | D12: 2600794 | I12: 27 | K12: 8 | O12: =E12*$E$5+F12*$F$5+G12*$G$5+H12*$H$5+I12*$I$5+J12*$J$5+K12*$K$5+L12*$L$5+M12*$M$5 | P12: TRƯỜNG SƠN
O13: =E13*$E$5+F13*$F$5+G13*$G$5+H13*$H$5+I13*$I$5+J13*$J$5+K13*$K$5+L13*$L$5+M13*$M$5
O14: =E14*$E$5+F14*$F$5+G14*$G$5+H14*$H$5+I14*$I$5+J14*$J$5+K14*$K$5+L14*$L$5+M14*$M$5
B15: 50 | O15: =E15*$E$5+F15*$F$5+G15*$G$5+H15*$H$5+I15*$I$5+J15*$J$5+K15*$K$5+L15*$L$5+M15*$M$5
B16: 51 | O16: =E16*$E$5+F16*$F$5+G16*$G$5+H16*$H$5+I16*$I$5+J16*$J$5+K16*$K$5+L16*$L$5+M16*$M$5
B17: KL CỌC NHẬP VỀ | E17: =SUM(E6:E16) | F17: =SUM(F6:F16) | G17: =SUM(G6:G16) | H17: =SUM(H6:H16) | I17: =SUM(I6:I16) | J17: =SUM(J6:J16) | K17: =SUM(K6:K16) | L17: =SUM(L6:L16) | M17: =SUM(M6:M16) | N17: =SUM(E17:M17) | O17: =SUM(O6:O16)
B18: KL CỌC THI CÔNG | E18: ='ÉP D300'!L61 | F18: ='ÉP D300'!M61 | G18: ='ÉP D300'!N61 | H18: ='ÉP D300'!O61 | I18: ='ÉP D300'!P61 | J18: ='ÉP D300'!Q61 | K18: ='ÉP D300'!R61 | L18: ='ÉP D300'!S61 | M18: ='ÉP D350'!T23 | N18: =J18+L18
B19: KL CỌC LOẠI
B20: KL CỌC CÒN LẠI | E20: =E17-E18-E19 | F20: =F17-F18-F19 | G20: =G17-G18-G19 | H20: =H17-H18-H19 | I20: =I17-I18-I19 | J20: =J17-J18-J19 | K20: =K17-K18-K19 | L20: =L17-L18-L19 | M20: =M17-M18-M19
B22: MAIN CONTRACTOR / NHÀ THẦU CHÍNH | L22: SUBCONTRACTORS / NHÀ THẦU PHỤ

Sheet công nhật
A1: STT | B1: Thới gian | E1: Nội dung công việc | F1: công nhật 300000 | G1: Số người
C2: Sáng | D2: Chiều
A3: 1 | B3: 46080 | C3: V | D3: V | E3: bò máy, vệ sinh , bơm mỡ | F3: 2 | G3: 2
A13: 4
F14: =SUM(F3:F13)

Sheet chuyển máy 420
B1: STT | C1: ngày tháng | D1: Tên máy | E1: TRUNG CHUYỂN MÁY | H1: số lần chuyển | I1: số lần tháo và lắp máy | J1: ghi chú
B2: 1 | C2: 46042 | D2: JVY420 | E2: KCN THĂNG LONG | G2: HÀ NAM | H2: 1 | I2: 2
B3: 2
B4: 3
B5: 4
D6: Tổng số lần chuyển máy | H6: =SUM(H2:H5) | I6: =SUM(I2:I5) | J6: =SUM(J2:J5)

Sheet Vât tư sửa máy
A1: ngày , tháng | B1: người sửa | C1: nội dung sửa chữa, bảo dưỡng | D1: Vật tư sửa chữa | F1: số lượng | G1: tên dự án
D2: Vật tư kỹ thuật mua | E2: Vật tư công công ty cấp
